<robot name="BECOV2" version="1.0">
  <joint name="LEG_LEFT_LEFT_JOINT" type="prismatic">
    <limit lower="-25.000" upper="0.00000" effort="1.00000" velocity="0.05000"/>
    <origin rpy="0.00000 0.00000 0.00000" xyz="-24.64902 -30.78809 -36.09229"/>
    <parent link="VISUAL_LEFTBODY_LINK"/>
    <child link="VISUAL_LEG_LEFT_LEFT_LINK"/>
    <axis xyz="0.00000 0.00000 1.00000"/>
  </joint>
  <joint name="LEG_LEFT_RIGHT_JOINT" type="prismatic">
    <limit lower="-25.00" upper="0.00000" effort="1.00000" velocity="0.05000"/>
    <origin rpy="0.00000 0.00000 0.00000" xyz="23.71511 -30.78809 -36.09229"/>
    <parent link="VISUAL_LEFTBODY_LINK"/>
    <child link="VISUAL_LEG_LEFT_RIGHT_LINK"/>
    <axis xyz="0.00000 0.00000 1.00000"/>
  </joint>
  <joint name="LEG_RIGHT_LEFT_JOINT" type="prismatic">
    <limit lower="-25.000" upper="0.00000" effort="1.00000" velocity="0.00000"/>
    <origin rpy="0.00000 0.00000 0.00000" xyz="26.45995 12.64404 -42.95021"/>
    <parent link="VISUAL_RIGHTBODY_LINK"/>
    <child link="VISUAL_LEG_RIGHT_LEFT_LINK"/>
    <axis xyz="0.00000 0.00000 1.00000"/>
  </joint>
  <joint name="LEG_RIGHT_RIGHT_JOINT" type="prismatic">
    <limit lower="-25.00000" upper="0.000" effort="1.00000" velocity="0.05000"/>
    <origin rpy="0.00000 0.00000 0.00000" xyz="-21.90419 12.64404 -42.45021"/>
    <parent link="VISUAL_RIGHTBODY_LINK"/>
    <child link="VISUAL_LEG_RIGHT_RIGHT_LINK"/>
    <axis xyz="0.00000 0.00000 1.00000"/>
  </joint>
  <joint name="RIGHTBODY_JOINT" type="fixed">
    <origin rpy="0.00000 0.00000 0.00000" xyz="-0.67174 33.11704 -21.14957"/>
    <parent link="VISUAL_SHAFT_LINK"/>
    <child link="VISUAL_RIGHTBODY_LINK"/>
  </joint>
  <joint name="SHAFT_JOINT" type="prismatic">
    <limit lower="0.00000" upper="100.0000" effort="1.00000" velocity="0.05000"/>
    <origin rpy="0.00000 0.00000 0.00000" xyz="-2.07309 67.14091 28.00749"/>
    <parent link="VISUAL_LEFTBODY_LINK"/>
    <child link="VISUAL_SHAFT_LINK"/>
    <axis xyz="0.00000 1.00000 0.00000"/>
  </joint>
  <link name="VISUAL_LEFTBODY_LINK">
    <collision name="LEFTBODYC1">
      <origin rpy="0.00000 0.00000 0.00000" xyz="-0.42717 -19.25141 6.22517"/>
      <geometry>
        <box size="0.7056577 0.6464597 0.2288614"/>
      </geometry>
    </collision>
    <collision name="LEFTBODYC2">
      <origin rpy="0.00000 0.00000 0.00000" xyz="-0.42718 -21.94500 -23.13796"/>
      <geometry>
        <box size="0.2303917 0.6464597 0.3785217"/>
      </geometry>
    </collision>
    <collision name="LEFTBODYC3">
      <origin rpy="0.00000 0.00000 0.00000" xyz="-32.62309 -21.94500 -23.13795"/>
      <geometry>
        <box size="0.0635735 0.6464596 0.3785216"/>
      </geometry>
    </collision>
    <collision name="LEFTBODYC4">
      <origin rpy="0.00000 0.00000 0.00000" xyz="-16.75294 -21.94500 -23.13795"/>
      <geometry>
        <box size="0.0635735 0.6464596 0.37852166"/>
      </geometry>
    </collision>
    <collision name="LEFTBODYC5">
      <origin rpy="0.00000 0.00000 0.00000" xyz="15.59485 -21.94500 -23.13796"/>
      <geometry>
        <box size="0.0635735 0.6464596 0.3785216"/>
      </geometry>
    </collision>
    <collision name="LEFTBODYC6">
      <origin rpy="0.00000 0.00000 0.00000" xyz="31.46501 -21.94500 -23.13796"/>
      <geometry>
        <box size="0.0635735 0.6464596 0.3785216"/>
      </geometry>
    </collision>
    <inertial>
      <inertia ixx="0.0001" ixy="0.00000" ixz="0.00000" iyy="0.0001" iyz="0.00000" izz="0.0001"/>
      <origin rpy="0.00000 0.00000 0.00000" xyz="-0.35669 -10.42801 0.85450"/>
      <mass value="0.00100"/>
    </inertial>
    <visual name="LEFTBODY_VISUAL">
      <origin rpy="0.00000 -1.57080 0.00000" xyz="-0.35669 -10.42800 0.85449"/>
      <geometry>
        <mesh filename="../meshes/stl/LEFTBODY.stl" scale="0.001 0.001 0.001"/>
      </geometry>
    </visual>
  </link>
  <link name="VISUAL_LEG_LEFT_LEFT_LINK">
    <collision name="LEG_LEFT_LEFTC1">
      <origin rpy="0.00000 0.00000 0.00000" xyz="0.22677 -1.58085 10.52444"/>
      <geometry>
        <box size="0.0635735 0.0673550 0.3892377"/>
      </geometry>
    </collision>
    <collision name="LEG_LEFT_LEFTC2">
      <origin rpy="0.00000 0.00000 0.00000" xyz="0.19421 -0.44572 -10.86936"/>
      <geometry>
        <mesh filename="../meshes/stl/Sphere.001.stl" scale="0.00332 0.00332 0.00332"/>
      </geometry>
    </collision>
    <inertial>
      <inertia ixx="0.0001" ixy="0.00000" ixz="0.00000" iyy="0.0001" iyz="0.00000" izz="0.0001"/>
      <origin rpy="0.00000 0.00000 0.00000" xyz="0.18863 -0.45370 -8.49117"/>
      <mass value="0.00100"/>
    </inertial>
    <visual name="LEG_LEFT_LEFT_VISUAL">
      <origin rpy="1.57080 0.00000 0.00000" xyz="0.18863 -0.45370 -8.60884"/>
      <geometry>
        <mesh filename="../meshes/stl/LEG_LEFT_RIGHT.stl" scale="0.001 0.001 0.001"/>
      </geometry>
    </visual>
  </link>
  <link name="VISUAL_LEG_LEFT_RIGHT_LINK">
    <collision name="LEG_LEFT_RIGHTC1">
      <origin rpy="0.00000 0.00000 0.00000" xyz="-0.45092 -1.58085 10.52444"/>
      <geometry>
        <box size="6.35735 6.73550 38.92377"/>
      </geometry>
    </collision>
    <collision name="LEG_LEFT_RIGHTC2">
      <origin rpy="0.00000 0.00000 0.00000" xyz="-0.41282 -0.44572 -10.86937"/>
      <geometry>
        <mesh filename="../meshes/stl/Sphere.002.stl" scale="0.00332 0.00332 0.00332"/>
      </geometry>
    </collision>
    <inertial>
      <inertia ixx="0.0001" ixy="0.00000" ixz="0.00000" iyy="0.0001" iyz="0.00000" izz="0.0001"/>
      <origin rpy="0.00000 0.00000 0.00000" xyz="-0.30030 -0.45370 -8.49117"/>
      <mass value="0.00100"/>
    </inertial>
    <visual name="LEG_LEFT_RIGHT_VISUAL">
      <origin rpy="1.57080 0.00000 0.00000" xyz="-0.30030 -0.45370 -8.60884"/>
      <geometry>
        <mesh filename="../meshes/stl/LEG_LEFT_LEFT.stl" scale="0.001 0.001 0.001"/>
      </geometry>
    </visual>
  </link>
  <link name="VISUAL_LEG_RIGHT_LEFT_LINK">
    <collision name="LEG_RIGHT_LEFTC1">
      <origin rpy="-0.00000 0.00000 0.00000" xyz="-0.23570 -0.72575 10.52444"/>
      <geometry>
        <box size="0.0635735 0.0673550 0.3892377"/>
      </geometry>
    </collision>
    <collision name="LEG_RIGHT_LEFTC2">
      <origin rpy="-0.00000 0.00000 0.00000" xyz="-0.26827 0.40938 -10.86937"/>
      <geometry>
        <mesh filename="../meshes/stl/Sphere.004.stl" scale="0.00332 0.00332 0.00332"/>
      </geometry>
    </collision>
    <inertial>
      <inertia ixx="0.0001" ixy="0.00000" ixz="0.00000" iyy="0.0001" iyz="0.00000" izz="0.0001"/>
      <origin rpy="0.00000 0.00000 0.00000" xyz="-0.30030 0.35611 -8.49116"/>
      <mass value="0.00100"/>
    </inertial>
    <visual name="LEG_RIGHT_LEFT_VISUAL">
      <origin rpy="1.57080 -0.00000 -3.14159" xyz="-0.30030 0.35611 -8.49116"/>
      <geometry>
        <mesh filename="../meshes/stl/LEG_RIGHT_RIGHT.stl" scale="0.001 0.001 0.001"/>
      </geometry>
    </visual>
  </link>
  <link name="VISUAL_LEG_RIGHT_RIGHT_LINK">
    <collision name="LEG_RIGHT_RIGHTC1">
      <origin rpy="-0.00000 0.00000 0.00000" xyz="0.22677 -0.72575 10.02445"/>
      <geometry>
        <box size="0.0635735 0.0673550 0.3892377"/>
      </geometry>
    </collision>
    <collision name="LEG_RIGHT_RIGHTC2">
      <origin rpy="-0.00000 0.00000 0.00000" xyz="0.19421 0.40937 -11.36936"/>
      <geometry>
        <mesh filename="../meshes/stl/Sphere.003.stl" scale="0.00332 0.00332 0.00332"/>
      </geometry>
    </collision>
    <inertial>
      <inertia ixx="0.0001" ixy="0.00000" ixz="0.00000" iyy="0.0001" iyz="0.00000" izz="0.0001"/>
      <origin rpy="0.00000 0.00000 0.00000" xyz="0.18863 0.35611 -8.99116"/>
      <mass value="0.00100"/>
    </inertial>
    <visual name="LEG_RIGHT_RIGHT_VISUAL">
      <origin rpy="1.57080 -0.00000 -3.14159" xyz="0.18863 0.35611 -8.99116"/>
      <geometry>
        <mesh filename="../meshes/stl/LEG_RIGHT_RIGHT.001.stl" scale="0.001 0.001 0.001"/>
      </geometry>
    </visual>
  </link>
  <link name="VISUAL_RIGHTBODY_LINK">
    <collision name="RIGHTBODYC1">
      <origin rpy="0.00000 0.00000 0.00000" xyz="2.31767 -12.37589 -0.63274"/>
      <geometry>
        <box size="0.7056577 0.6464595 0.2288614"/>
      </geometry>
    </collision>
    <collision name="RIGHTBODYC2">
      <origin rpy="0.00000 0.00000 0.00000" xyz="2.31766 -15.13247 -29.99588"/>
      <geometry>
        <box size="0.2303917 0.6464596 0.3785217"/>
      </geometry>
    </collision>
    <collision name="RIGHTBODYC3">
      <origin rpy="0.00000 0.00000 0.00000" xyz="-29.87826 -15.13247 -29.99587"/>
      <geometry>
        <box size="0.0635735 0.6464595 0.3785216"/>
      </geometry>
    </collision>
    <collision name="RIGHTBODYC4">
      <origin rpy="0.00000 0.00000 0.00000" xyz="-14.00810 -15.13247 -29.99587"/>
      <geometry>
        <box size="0.0635735 0.6464595 0.3785216"/>
      </geometry>
    </collision>
    <collision name="RIGHTBODYC5">
      <origin rpy="0.00000 0.00000 0.00000" xyz="18.33969 -15.13247 -29.99588"/>
      <geometry>
        <box size="0.0635735 0.6464595 0.3785216"/>
      </geometry>
    </collision>
    <collision name="RIGHTBODYC6">
      <origin rpy="0.00000 0.00000 0.00000" xyz="34.20985 -15.13247 -29.99589"/>
      <geometry>
        <box size="0.0635735 0.6464595 0.3785216"/>
      </geometry>
    </collision>
    <inertial>
      <inertia ixx="0.0001" ixy="0.00000" ixz="0.00000" iyy="0.0001" iyz="0.00000" izz="0.0001"/>
      <origin rpy="0.00000 0.00000 0.00000" xyz="1.85425 -16.99135 19.61997"/>
      <mass value="0.00100"/>
    </inertial>
    <visual name="RIGHTBODY_VISUAL">
      <origin rpy="-3.14159 -1.57080 0.00000" xyz="1.85425 -16.99135 -21.12375"/>
      <geometry>
        <mesh filename="../meshes/stl/RIGHTBODY.stl" scale="0.01 0.01 0.01"/>
      </geometry>
    </visual>
  </link>
  <link name="VISUAL_SHAFT_LINK">
    <collision name="SHAFTC1">
      <origin rpy="0.00000 0.00000 0.00000" xyz="-0.09157 -7.46644 -1.53009"/>
      <geometry>
        <box size="0.1140243 1.1669112 0.1140242"/>
      </geometry>
    </collision>
    <inertial>
      <inertia ixx="0.0001" ixy="0.00000" ixz="0.00000" iyy="0.0001" iyz="0.00000" izz="0.0001"/>
      <origin rpy="0.00000 0.00000 0.00000" xyz="-0.02829 -3.15881 -1.52960"/>
      <mass value="0.00100"/>
    </inertial>
    <visual name="SHAFT_VISUAL">
      <origin rpy="0.00000 0.00000 0.00000" xyz="-0.02829 -3.15881 -1.52960"/>
      <geometry>
        <mesh filename="../meshes/stl/SHAFT.stl" scale="0.01 0.01 0.01"/>
      </geometry>
    </visual>
  </link>
</robot>